<?xml version="1.0"?>
<robot name="my_robot" xmlns:xacro="http://www.ros.org/wiki/xacro">

  <xacro:include filename="inertial_macros.xacro" />

  <material name="grey">
    <color rgba="0.7 0.7 0.7 1" /> 
  </material>
  <material name="white">
    <color rgba="1 1 1 1" /> 
  </material>
  <material name="green">
    <color rgba="0 1 0 1" /> 
  </material>
  <material name="blue">
    <color rgba="0 0 1 1" /> 
  </material>

  <link name="base_footprint"/>

  <link name="base_link">
    <visual>
      <geometry>
        <box size="0.58 0.4 0.38" /> 
      </geometry>
      <origin xyz="0 0 0.19" rpy="0 0 0" /> 
      <material name="grey" />
    </visual>
    <collision>
      <origin xyz="0.29 0 0.19" rpy="0 0 0" />
      <geometry>
        <box size="0.58 0.4 0.38" />
      </geometry>
    </collision>
    <xacro:inertial_box mass="8" x="0.58" y="0.4" z="0.38">
      <origin xyz="0.29 0 0.19" rpy="0 0 0"/>
    </xacro:inertial_box>           
  </link>

  <link name="left_wheel">
    <visual>
      <geometry>		
        <cylinder radius="0.083" length="0.05" />
      </geometry>
      <origin xyz="0 0 0" rpy="1.57 0 0" />
      <material name="green" />
    </visual>
    <collision>
      <geometry>
        <sphere radius="0.083"/>
      </geometry>
      <origin xyz="0 0 0" rpy="1.57 0 0" />
    </collision>
    <xacro:inertial_cylinder mass="2" length="0.05" radius="0.083">
      <origin xyz="0 0 0" rpy="1.57 0 0"/>
    </xacro:inertial_cylinder>
  </link>

  <link name="right_wheel">
    <visual>
      <geometry>		
        <cylinder radius="0.083" length="0.05" />
      </geometry>
      <origin xyz="0 0 0" rpy="1.57 0 0" />
      <material name="green" />
    </visual>
    <collision>
      <geometry>
        <sphere radius="0.083"/>
      </geometry>
      <origin xyz="0 0 0" rpy="1.57 0 0" />
    </collision>
    <xacro:inertial_cylinder mass="2" length="0.05" radius="0.083">
      <origin xyz="0 0 0" rpy="1.57 0 0"/>
    </xacro:inertial_cylinder>
  </link>

  <link name="caster_wheel">
    <visual>
      <geometry>		
        <sphere radius="0.04" />
      </geometry>
      <origin xyz="0 0 0" rpy="1.57 0 0" />
      <material name="green" />
    </visual>
    <collision>
      <geometry>
        <sphere radius="0.04"/>
      </geometry>
      <origin xyz="0 0 0" rpy="0 0 0" />
    </collision>
    <xacro:inertial_cylinder mass="1" length="0.05" radius="0.04">
      <origin xyz="0 0 0" rpy="0 0 0"/>
    </xacro:inertial_cylinder>
  </link>

   <link name="ultrasonic_sensor">
    <visual>
      <geometry>		
        <box size = "0.015 0.06 0.04" />
      </geometry>
      <origin xyz="0 0 0" rpy="0 0 0" />
      <material name="blue" />
    </visual>
    <collision>
      <geometry>
        <box size = "0.015 0.06 0.04" />
      </geometry>
      <origin xyz="0 0 0" rpy="0 0 0" />
    </collision>
    <xacro:inertial_box mass="0.05" x="0.015" y="0.06" z="0.04">
      <origin xyz="0 0 0" rpy="0 0 0"/>
    </xacro:inertial_box>
  </link>

  <joint name="base_joint" type="fixed">
    <parent link="base_footprint"/>
    <child link="base_link" />
    <origin xyz="0 0 0.108" rpy="0 0 0" />
  </joint>

  <joint name="ultrasonic_sensor_joint" type="fixed">
    <parent link="base_link"/>
    <child link="ultrasonic_sensor" />
    <origin xyz="0.3 0 0.03" rpy="0 0 0" />
  </joint>

  <joint name="left_wheel_joint" type="continuous">
    <parent link="base_link"/>
    <child link="left_wheel"/>
    <origin xyz="0.22 0.225 0" rpy="0 0 0" /> 
    <axis xyz="0 1 0" />
  </joint>

  <joint name="right_wheel_joint" type="continuous">
    <parent link="base_link"/>
    <child link="right_wheel"/>
    <origin xyz="0.22 -0.225 0" rpy="0 0 0" /> 
    <axis xyz="0 1 0" />
  </joint>

  <joint name="caster_wheel_joint" type="fixed">
    <parent link="base_link"/>
    <child link="caster_wheel"/>
    <origin xyz="-0.22 0 -0.08" rpy="0 0 0"/> 
  </joint>

</robot>